<?xml version="1.0" encoding="UTF-8"?>
<!-- Generated by org.testng.reporters.JUnitXMLReporter -->
<testsuite ignored="0" hostname="DESKTOP-TP6MMLS" failures="2" tests="4" name="Default test" time="12.592" errors="0" timestamp="2025-04-17T13:44:23 IST">
  <testcase classname="com.swagLabs.testScripts.TC_001" name="validateTitle" time="0.032"/>
  <testcase classname="com.swagLabs.testScripts.TC_001" name="validateUrl" time="0.039">
    <failure type="java.lang.AssertionError" message="expected [https://www.saucedemo.com/v1/] but found [https://www.saucedemo.com/v1/index.html]">
      <![CDATA[java.lang.AssertionError: expected [https://www.saucedemo.com/v1/] but found [https://www.saucedemo.com/v1/index.html]
at org.testng.Assert.fail(Assert.java:111)
at org.testng.Assert.failNotEquals(Assert.java:1590)
at org.testng.Assert.assertEqualsImpl(Assert.java:150)
at org.testng.Assert.assertEquals(Assert.java:132)
at org.testng.Assert.assertEquals(Assert.java:656)
at org.testng.Assert.assertEquals(Assert.java:666)
at com.swagLabs.testScripts.TC_001.validateUrl(TC_001.java:37)
at java.base/jdk.internal.reflect.DirectMethodHandleAccessor.invoke(DirectMethodHandleAccessor.java:103)
at java.base/java.lang.reflect.Method.invoke(Method.java:580)
at org.testng.internal.invokers.MethodInvocationHelper.invokeMethod(MethodInvocationHelper.java:141)
at org.testng.internal.invokers.TestInvoker.invokeMethod(TestInvoker.java:687)
at org.testng.internal.invokers.TestInvoker.invokeTestMethod(TestInvoker.java:230)
at org.testng.internal.invokers.MethodRunner.runInSequence(MethodRunner.java:63)
at org.testng.internal.invokers.TestInvoker$MethodInvocationAgent.invoke(TestInvoker.java:995)
at org.testng.internal.invokers.TestInvoker.invokeTestMethods(TestInvoker.java:203)
at org.testng.internal.invokers.TestMethodWorker.invokeTestMethods(TestMethodWorker.java:154)
at org.testng.internal.invokers.TestMethodWorker.run(TestMethodWorker.java:134)
at java.base/java.util.ArrayList.forEach(ArrayList.java:1597)
at org.testng.TestRunner.privateRun(TestRunner.java:741)
at org.testng.TestRunner.run(TestRunner.java:616)
at org.testng.SuiteRunner.runTest(SuiteRunner.java:421)
at org.testng.SuiteRunner.runSequentially(SuiteRunner.java:413)
at org.testng.SuiteRunner.privateRun(SuiteRunner.java:373)
at org.testng.SuiteRunner.run(SuiteRunner.java:312)
at org.testng.SuiteRunnerWorker.runSuite(SuiteRunnerWorker.java:52)
at org.testng.SuiteRunnerWorker.run(SuiteRunnerWorker.java:95)
at org.testng.TestNG.runSuitesSequentially(TestNG.java:1274)
at org.testng.TestNG.runSuitesLocally(TestNG.java:1208)
at org.testng.TestNG.runSuites(TestNG.java:1112)
at org.testng.TestNG.run(TestNG.java:1079)
at org.testng.remote.AbstractRemoteTestNG.run(AbstractRemoteTestNG.java:115)
at org.testng.remote.RemoteTestNG.initAndRun(RemoteTestNG.java:293)
at org.testng.remote.RemoteTestNG.main(RemoteTestNG.java:91)
]]>
    </failure>
  </testcase> <!-- validateUrl -->
  <testcase classname="com.swagLabs.testScripts.TC_001" name="validate_loginLogo" time="0.092"/>
  <testcase classname="com.swagLabs.testScripts.TC_001" name="validate_login" time="2.793">
    <failure type="java.lang.AssertionError" message="expected [SwagLabs] but found [Swag Labs]">
      <![CDATA[java.lang.AssertionError: expected [SwagLabs] but found [Swag Labs]
at org.testng.Assert.fail(Assert.java:111)
at org.testng.Assert.failNotEquals(Assert.java:1590)
at org.testng.Assert.assertEqualsImpl(Assert.java:150)
at org.testng.Assert.assertEquals(Assert.java:132)
at org.testng.Assert.assertEquals(Assert.java:656)
at org.testng.Assert.assertEquals(Assert.java:666)
at com.swagLabs.testScripts.TC_001.validate_login(TC_001.java:54)
at java.base/jdk.internal.reflect.DirectMethodHandleAccessor.invoke(DirectMethodHandleAccessor.java:103)
at java.base/java.lang.reflect.Method.invoke(Method.java:580)
at org.testng.internal.invokers.MethodInvocationHelper.invokeMethod(MethodInvocationHelper.java:141)
at org.testng.internal.invokers.TestInvoker.invokeMethod(TestInvoker.java:687)
at org.testng.internal.invokers.TestInvoker.invokeTestMethod(TestInvoker.java:230)
at org.testng.internal.invokers.MethodRunner.runInSequence(MethodRunner.java:63)
at org.testng.internal.invokers.TestInvoker$MethodInvocationAgent.invoke(TestInvoker.java:995)
at org.testng.internal.invokers.TestInvoker.invokeTestMethods(TestInvoker.java:203)
at org.testng.internal.invokers.TestMethodWorker.invokeTestMethods(TestMethodWorker.java:154)
at org.testng.internal.invokers.TestMethodWorker.run(TestMethodWorker.java:134)
at java.base/java.util.ArrayList.forEach(ArrayList.java:1597)
at org.testng.TestRunner.privateRun(TestRunner.java:741)
at org.testng.TestRunner.run(TestRunner.java:616)
at org.testng.SuiteRunner.runTest(SuiteRunner.java:421)
at org.testng.SuiteRunner.runSequentially(SuiteRunner.java:413)
at org.testng.SuiteRunner.privateRun(SuiteRunner.java:373)
at org.testng.SuiteRunner.run(SuiteRunner.java:312)
at org.testng.SuiteRunnerWorker.runSuite(SuiteRunnerWorker.java:52)
at org.testng.SuiteRunnerWorker.run(SuiteRunnerWorker.java:95)
at org.testng.TestNG.runSuitesSequentially(TestNG.java:1274)
at org.testng.TestNG.runSuitesLocally(TestNG.java:1208)
at org.testng.TestNG.runSuites(TestNG.java:1112)
at org.testng.TestNG.run(TestNG.java:1079)
at org.testng.remote.AbstractRemoteTestNG.run(AbstractRemoteTestNG.java:115)
at org.testng.remote.RemoteTestNG.initAndRun(RemoteTestNG.java:293)
at org.testng.remote.RemoteTestNG.main(RemoteTestNG.java:91)
]]>
    </failure>
  </testcase> <!-- validate_login -->
</testsuite> <!-- Default test -->
